2025-10-25 17:33:34,927 - compliance_checker - INFO - Running compliance tests for KNG
2025-10-25 17:33:34,927 - compliance_checker - ERROR - Error calculating summary metrics for KNG: 'price'
Traceback (most recent call last):
  File "C:\Users\PatrickCorcoran\anaconda3\Lib\site-packages\pandas\core\indexes\base.py", line 3791, in get_loc
    return self._engine.get_loc(casted_key)
           ^^^^^^^^^^^^^^^^^^^^^^^^^^^^^^^^
  File "index.pyx", line 152, in pandas._libs.index.IndexEngine.get_loc
  File "index.pyx", line 181, in pandas._libs.index.IndexEngine.get_loc
  File "pandas\_libs\hashtable_class_helper.pxi", line 7080, in pandas._libs.hashtable.PyObjectHashTable.get_item
  File "pandas\_libs\hashtable_class_helper.pxi", line 7088, in pandas._libs.hashtable.PyObjectHashTable.get_item
KeyError: 'price'

The above exception was the direct cause of the following exception:

Traceback (most recent call last):
  File "C:\Users\PatrickCorcoran\OneDrive - Vest Financial\Documents\Coding\VestFundManager\services\compliance_checker.py", line 73, in run_compliance_tests
    summary_metrics = self.calculate_summary_metrics(fund)
                      ^^^^^^^^^^^^^^^^^^^^^^^^^^^^^^^^^^^^
  File "C:\Users\PatrickCorcoran\OneDrive - Vest Financial\Documents\Coding\VestFundManager\services\compliance_checker.py", line 103, in calculate_summary_metrics
    'equity_market_value': fund.total_equity_value,
                           ^^^^^^^^^^^^^^^^^^^^^^^
  File "C:\Users\PatrickCorcoran\OneDrive - Vest Financial\Documents\Coding\VestFundManager\domain\fund.py", line 72, in total_equity_value
    return (self.data.current.equity['price'] * self.data.current.equity['quantity']).sum()
            ~~~~~~~~~~~~~~~~~~~~~~~~^^^^^^^^^
  File "C:\Users\PatrickCorcoran\anaconda3\Lib\site-packages\pandas\core\frame.py", line 3893, in __getitem__
    indexer = self.columns.get_loc(key)
              ^^^^^^^^^^^^^^^^^^^^^^^^^
  File "C:\Users\PatrickCorcoran\anaconda3\Lib\site-packages\pandas\core\indexes\base.py", line 3798, in get_loc
    raise KeyError(key) from err
KeyError: 'price'
2025-10-25 17:33:34,947 - compliance_checker - ERROR - Error executing gics_compliance for fund KNG: 'ComplianceChecker' object has no attribute 'fund_results'
Traceback (most recent call last):
  File "C:\Users\PatrickCorcoran\OneDrive - Vest Financial\Documents\Coding\VestFundManager\services\compliance_checker.py", line 85, in run_compliance_tests
    result = test_func(fund)
             ^^^^^^^^^^^^^^^
  File "C:\Users\PatrickCorcoran\OneDrive - Vest Financial\Documents\Coding\VestFundManager\services\compliance_checker.py", line 320, in gics_compliance
    fund_data = self.fund_results.get(etf, {})
                ^^^^^^^^^^^^^^^^^
AttributeError: 'ComplianceChecker' object has no attribute 'fund_results'
2025-10-25 17:33:34,948 - compliance_checker - ERROR - Error executing diversification_40act_check for fund KNG: 'Fund' object has no attribute 'is_private_fund'
Traceback (most recent call last):
  File "C:\Users\PatrickCorcoran\OneDrive - Vest Financial\Documents\Coding\VestFundManager\services\compliance_checker.py", line 85, in run_compliance_tests
    result = test_func(fund)
             ^^^^^^^^^^^^^^^
  File "C:\Users\PatrickCorcoran\OneDrive - Vest Financial\Documents\Coding\VestFundManager\services\compliance_checker.py", line 221, in diversification_40act_check
    if fund.is_private_fund:
       ^^^^^^^^^^^^^^^^^^^^
AttributeError: 'Fund' object has no attribute 'is_private_fund'
2025-10-25 17:33:34,959 - compliance_checker - INFO - Running compliance tests for FDND
2025-10-25 17:33:34,959 - compliance_checker - ERROR - Error calculating summary metrics for FDND: 'price'
Traceback (most recent call last):
  File "C:\Users\PatrickCorcoran\anaconda3\Lib\site-packages\pandas\core\indexes\base.py", line 3791, in get_loc
    return self._engine.get_loc(casted_key)
           ^^^^^^^^^^^^^^^^^^^^^^^^^^^^^^^^
  File "index.pyx", line 152, in pandas._libs.index.IndexEngine.get_loc
  File "index.pyx", line 181, in pandas._libs.index.IndexEngine.get_loc
  File "pandas\_libs\hashtable_class_helper.pxi", line 7080, in pandas._libs.hashtable.PyObjectHashTable.get_item
  File "pandas\_libs\hashtable_class_helper.pxi", line 7088, in pandas._libs.hashtable.PyObjectHashTable.get_item
KeyError: 'price'

The above exception was the direct cause of the following exception:

Traceback (most recent call last):
  File "C:\Users\PatrickCorcoran\OneDrive - Vest Financial\Documents\Coding\VestFundManager\services\compliance_checker.py", line 73, in run_compliance_tests
    summary_metrics = self.calculate_summary_metrics(fund)
                      ^^^^^^^^^^^^^^^^^^^^^^^^^^^^^^^^^^^^
  File "C:\Users\PatrickCorcoran\OneDrive - Vest Financial\Documents\Coding\VestFundManager\services\compliance_checker.py", line 103, in calculate_summary_metrics
    'equity_market_value': fund.total_equity_value,
                           ^^^^^^^^^^^^^^^^^^^^^^^
  File "C:\Users\PatrickCorcoran\OneDrive - Vest Financial\Documents\Coding\VestFundManager\domain\fund.py", line 72, in total_equity_value
    return (self.data.current.equity['price'] * self.data.current.equity['quantity']).sum()
            ~~~~~~~~~~~~~~~~~~~~~~~~^^^^^^^^^
  File "C:\Users\PatrickCorcoran\anaconda3\Lib\site-packages\pandas\core\frame.py", line 3893, in __getitem__
    indexer = self.columns.get_loc(key)
              ^^^^^^^^^^^^^^^^^^^^^^^^^
  File "C:\Users\PatrickCorcoran\anaconda3\Lib\site-packages\pandas\core\indexes\base.py", line 3798, in get_loc
    raise KeyError(key) from err
KeyError: 'price'
2025-10-25 17:33:34,962 - compliance_checker - ERROR - Error executing gics_compliance for fund FDND: 'ComplianceChecker' object has no attribute 'fund_results'
Traceback (most recent call last):
  File "C:\Users\PatrickCorcoran\OneDrive - Vest Financial\Documents\Coding\VestFundManager\services\compliance_checker.py", line 85, in run_compliance_tests
    result = test_func(fund)
             ^^^^^^^^^^^^^^^
  File "C:\Users\PatrickCorcoran\OneDrive - Vest Financial\Documents\Coding\VestFundManager\services\compliance_checker.py", line 320, in gics_compliance
    fund_data = self.fund_results.get(etf, {})
                ^^^^^^^^^^^^^^^^^
AttributeError: 'ComplianceChecker' object has no attribute 'fund_results'
2025-10-25 17:33:34,963 - compliance_checker - ERROR - Error executing diversification_40act_check for fund FDND: 'Fund' object has no attribute 'is_private_fund'
Traceback (most recent call last):
  File "C:\Users\PatrickCorcoran\OneDrive - Vest Financial\Documents\Coding\VestFundManager\services\compliance_checker.py", line 85, in run_compliance_tests
    result = test_func(fund)
             ^^^^^^^^^^^^^^^
  File "C:\Users\PatrickCorcoran\OneDrive - Vest Financial\Documents\Coding\VestFundManager\services\compliance_checker.py", line 221, in diversification_40act_check
    if fund.is_private_fund:
       ^^^^^^^^^^^^^^^^^^^^
AttributeError: 'Fund' object has no attribute 'is_private_fund'
2025-10-25 17:33:34,973 - compliance_checker - INFO - Running compliance tests for DOGG
2025-10-25 17:33:34,974 - compliance_checker - ERROR - Error calculating summary metrics for DOGG: 'price'
Traceback (most recent call last):
  File "C:\Users\PatrickCorcoran\anaconda3\Lib\site-packages\pandas\core\indexes\base.py", line 3791, in get_loc
    return self._engine.get_loc(casted_key)
           ^^^^^^^^^^^^^^^^^^^^^^^^^^^^^^^^
  File "index.pyx", line 152, in pandas._libs.index.IndexEngine.get_loc
  File "index.pyx", line 181, in pandas._libs.index.IndexEngine.get_loc
  File "pandas\_libs\hashtable_class_helper.pxi", line 7080, in pandas._libs.hashtable.PyObjectHashTable.get_item
  File "pandas\_libs\hashtable_class_helper.pxi", line 7088, in pandas._libs.hashtable.PyObjectHashTable.get_item
KeyError: 'price'

The above exception was the direct cause of the following exception:

Traceback (most recent call last):
  File "C:\Users\PatrickCorcoran\OneDrive - Vest Financial\Documents\Coding\VestFundManager\services\compliance_checker.py", line 73, in run_compliance_tests
    summary_metrics = self.calculate_summary_metrics(fund)
                      ^^^^^^^^^^^^^^^^^^^^^^^^^^^^^^^^^^^^
  File "C:\Users\PatrickCorcoran\OneDrive - Vest Financial\Documents\Coding\VestFundManager\services\compliance_checker.py", line 103, in calculate_summary_metrics
    'equity_market_value': fund.total_equity_value,
                           ^^^^^^^^^^^^^^^^^^^^^^^
  File "C:\Users\PatrickCorcoran\OneDrive - Vest Financial\Documents\Coding\VestFundManager\domain\fund.py", line 72, in total_equity_value
    return (self.data.current.equity['price'] * self.data.current.equity['quantity']).sum()
            ~~~~~~~~~~~~~~~~~~~~~~~~^^^^^^^^^
  File "C:\Users\PatrickCorcoran\anaconda3\Lib\site-packages\pandas\core\frame.py", line 3893, in __getitem__
    indexer = self.columns.get_loc(key)
              ^^^^^^^^^^^^^^^^^^^^^^^^^
  File "C:\Users\PatrickCorcoran\anaconda3\Lib\site-packages\pandas\core\indexes\base.py", line 3798, in get_loc
    raise KeyError(key) from err
KeyError: 'price'
2025-10-25 17:33:34,976 - compliance_checker - ERROR - Error executing gics_compliance for fund DOGG: 'ComplianceChecker' object has no attribute 'fund_results'
Traceback (most recent call last):
  File "C:\Users\PatrickCorcoran\OneDrive - Vest Financial\Documents\Coding\VestFundManager\services\compliance_checker.py", line 85, in run_compliance_tests
    result = test_func(fund)
             ^^^^^^^^^^^^^^^
  File "C:\Users\PatrickCorcoran\OneDrive - Vest Financial\Documents\Coding\VestFundManager\services\compliance_checker.py", line 320, in gics_compliance
    fund_data = self.fund_results.get(etf, {})
                ^^^^^^^^^^^^^^^^^
AttributeError: 'ComplianceChecker' object has no attribute 'fund_results'
2025-10-25 17:33:34,979 - compliance_checker - ERROR - Error executing diversification_40act_check for fund DOGG: 'Fund' object has no attribute 'is_private_fund'
Traceback (most recent call last):
  File "C:\Users\PatrickCorcoran\OneDrive - Vest Financial\Documents\Coding\VestFundManager\services\compliance_checker.py", line 85, in run_compliance_tests
    result = test_func(fund)
             ^^^^^^^^^^^^^^^
  File "C:\Users\PatrickCorcoran\OneDrive - Vest Financial\Documents\Coding\VestFundManager\services\compliance_checker.py", line 221, in diversification_40act_check
    if fund.is_private_fund:
       ^^^^^^^^^^^^^^^^^^^^
AttributeError: 'Fund' object has no attribute 'is_private_fund'
2025-10-25 17:34:29,003 - compliance_checker - INFO - Running compliance tests for DOGG
2025-10-25 17:35:59,734 - compliance_checker - ERROR - Error calculating summary metrics for DOGG: 'price'
Traceback (most recent call last):
  File "C:\Users\PatrickCorcoran\anaconda3\Lib\site-packages\pandas\core\indexes\base.py", line 3791, in get_loc
    return self._engine.get_loc(casted_key)
           ^^^^^^^^^^^^^^^^^^^^^^^^^^^^^^^^
  File "index.pyx", line 152, in pandas._libs.index.IndexEngine.get_loc
  File "index.pyx", line 181, in pandas._libs.index.IndexEngine.get_loc
  File "pandas\_libs\hashtable_class_helper.pxi", line 7080, in pandas._libs.hashtable.PyObjectHashTable.get_item
  File "pandas\_libs\hashtable_class_helper.pxi", line 7088, in pandas._libs.hashtable.PyObjectHashTable.get_item
KeyError: 'price'

The above exception was the direct cause of the following exception:

Traceback (most recent call last):
  File "C:\Users\PatrickCorcoran\OneDrive - Vest Financial\Documents\Coding\VestFundManager\services\compliance_checker.py", line 73, in run_compliance_tests
    summary_metrics = self.calculate_summary_metrics(fund)
                      ^^^^^^^^^^^^^^^^^^^^^^^^^^^^^^^^^^^^
  File "C:\Users\PatrickCorcoran\OneDrive - Vest Financial\Documents\Coding\VestFundManager\services\compliance_checker.py", line 103, in calculate_summary_metrics
    'equity_market_value': fund.total_equity_value,
                           ^^^^^^^^^^^^^^^^^^^^^^^
  File "C:\Users\PatrickCorcoran\OneDrive - Vest Financial\Documents\Coding\VestFundManager\domain\fund.py", line 72, in total_equity_value
    return (self.data.current.equity['price'] * self.data.current.equity['quantity']).sum()
            ~~~~~~~~~~~~~~~~~~~~~~~~^^^^^^^^^
  File "C:\Users\PatrickCorcoran\anaconda3\Lib\site-packages\pandas\core\frame.py", line 3893, in __getitem__
    indexer = self.columns.get_loc(key)
              ^^^^^^^^^^^^^^^^^^^^^^^^^
  File "C:\Users\PatrickCorcoran\anaconda3\Lib\site-packages\pandas\core\indexes\base.py", line 3798, in get_loc
    raise KeyError(key) from err
KeyError: 'price'
2025-10-25 17:35:59,752 - compliance_checker - ERROR - Error executing gics_compliance for fund DOGG: 'ComplianceChecker' object has no attribute 'fund_results'
Traceback (most recent call last):
  File "C:\Users\PatrickCorcoran\OneDrive - Vest Financial\Documents\Coding\VestFundManager\services\compliance_checker.py", line 85, in run_compliance_tests
    result = test_func(fund)
             ^^^^^^^^^^^^^^^
  File "C:\Users\PatrickCorcoran\OneDrive - Vest Financial\Documents\Coding\VestFundManager\services\compliance_checker.py", line 320, in gics_compliance
    fund_data = self.fund_results.get(etf, {})
                ^^^^^^^^^^^^^^^^^
AttributeError: 'ComplianceChecker' object has no attribute 'fund_results'
2025-10-25 17:35:59,799 - compliance_checker - ERROR - Error executing diversification_40act_check for fund DOGG: 'Fund' object has no attribute 'is_private_fund'
Traceback (most recent call last):
  File "C:\Users\PatrickCorcoran\OneDrive - Vest Financial\Documents\Coding\VestFundManager\services\compliance_checker.py", line 85, in run_compliance_tests
    result = test_func(fund)
             ^^^^^^^^^^^^^^^
  File "C:\Users\PatrickCorcoran\OneDrive - Vest Financial\Documents\Coding\VestFundManager\services\compliance_checker.py", line 221, in diversification_40act_check
    if fund.is_private_fund:
       ^^^^^^^^^^^^^^^^^^^^
AttributeError: 'Fund' object has no attribute 'is_private_fund'
2025-10-25 17:35:59,912 - compliance_checker - INFO - Running compliance tests for KNG
2025-10-25 17:37:37,761 - compliance_checker - INFO - Running compliance tests for DOGG
2025-10-25 17:37:44,698 - compliance_checker - ERROR - Error calculating summary metrics for DOGG: 'price'
Traceback (most recent call last):
  File "C:\Users\PatrickCorcoran\anaconda3\Lib\site-packages\pandas\core\indexes\base.py", line 3791, in get_loc
    return self._engine.get_loc(casted_key)
           ^^^^^^^^^^^^^^^^^^^^^^^^^^^^^^^^
  File "index.pyx", line 152, in pandas._libs.index.IndexEngine.get_loc
  File "index.pyx", line 181, in pandas._libs.index.IndexEngine.get_loc
  File "pandas\_libs\hashtable_class_helper.pxi", line 7080, in pandas._libs.hashtable.PyObjectHashTable.get_item
  File "pandas\_libs\hashtable_class_helper.pxi", line 7088, in pandas._libs.hashtable.PyObjectHashTable.get_item
KeyError: 'price'

The above exception was the direct cause of the following exception:

Traceback (most recent call last):
  File "C:\Users\PatrickCorcoran\OneDrive - Vest Financial\Documents\Coding\VestFundManager\services\compliance_checker.py", line 73, in run_compliance_tests
    summary_metrics = self.calculate_summary_metrics(fund)
                      ^^^^^^^^^^^^^^^^^^^^^^^^^^^^^^^^^^^^
  File "C:\Users\PatrickCorcoran\OneDrive - Vest Financial\Documents\Coding\VestFundManager\services\compliance_checker.py", line 103, in calculate_summary_metrics
    'equity_market_value': fund.total_equity_value,
                           ^^^^^^^^^^^^^^^^^^^^^^^
  File "C:\Users\PatrickCorcoran\OneDrive - Vest Financial\Documents\Coding\VestFundManager\domain\fund.py", line 72, in total_equity_value
    return (self.data.current.equity['price'] * self.data.current.equity['quantity']).sum()
            ~~~~~~~~~~~~~~~~~~~~~~~~^^^^^^^^^
  File "C:\Users\PatrickCorcoran\anaconda3\Lib\site-packages\pandas\core\frame.py", line 3893, in __getitem__
    indexer = self.columns.get_loc(key)
              ^^^^^^^^^^^^^^^^^^^^^^^^^
  File "C:\Users\PatrickCorcoran\anaconda3\Lib\site-packages\pandas\core\indexes\base.py", line 3798, in get_loc
    raise KeyError(key) from err
KeyError: 'price'
2025-10-25 17:37:44,715 - compliance_checker - ERROR - Error executing gics_compliance for fund DOGG: 'ComplianceChecker' object has no attribute 'fund_results'
Traceback (most recent call last):
  File "C:\Users\PatrickCorcoran\OneDrive - Vest Financial\Documents\Coding\VestFundManager\services\compliance_checker.py", line 85, in run_compliance_tests
    result = test_func(fund)
             ^^^^^^^^^^^^^^^
  File "C:\Users\PatrickCorcoran\OneDrive - Vest Financial\Documents\Coding\VestFundManager\services\compliance_checker.py", line 320, in gics_compliance
    fund_data = self.fund_results.get(etf, {})
                ^^^^^^^^^^^^^^^^^
AttributeError: 'ComplianceChecker' object has no attribute 'fund_results'
2025-10-25 17:37:44,762 - compliance_checker - ERROR - Error executing diversification_40act_check for fund DOGG: 'Fund' object has no attribute 'is_private_fund'
Traceback (most recent call last):
  File "C:\Users\PatrickCorcoran\OneDrive - Vest Financial\Documents\Coding\VestFundManager\services\compliance_checker.py", line 85, in run_compliance_tests
    result = test_func(fund)
             ^^^^^^^^^^^^^^^
  File "C:\Users\PatrickCorcoran\OneDrive - Vest Financial\Documents\Coding\VestFundManager\services\compliance_checker.py", line 221, in diversification_40act_check
    if fund.is_private_fund:
       ^^^^^^^^^^^^^^^^^^^^
AttributeError: 'Fund' object has no attribute 'is_private_fund'
2025-10-25 17:38:32,022 - compliance_checker - INFO - Running compliance tests for DOGG
2025-10-25 17:38:32,023 - compliance_checker - ERROR - Error calculating summary metrics for DOGG: 'price'
Traceback (most recent call last):
  File "C:\Users\PatrickCorcoran\anaconda3\Lib\site-packages\pandas\core\indexes\base.py", line 3791, in get_loc
    return self._engine.get_loc(casted_key)
           ^^^^^^^^^^^^^^^^^^^^^^^^^^^^^^^^
  File "index.pyx", line 152, in pandas._libs.index.IndexEngine.get_loc
  File "index.pyx", line 181, in pandas._libs.index.IndexEngine.get_loc
  File "pandas\_libs\hashtable_class_helper.pxi", line 7080, in pandas._libs.hashtable.PyObjectHashTable.get_item
  File "pandas\_libs\hashtable_class_helper.pxi", line 7088, in pandas._libs.hashtable.PyObjectHashTable.get_item
KeyError: 'price'

The above exception was the direct cause of the following exception:

Traceback (most recent call last):
  File "C:\Users\PatrickCorcoran\OneDrive - Vest Financial\Documents\Coding\VestFundManager\services\compliance_checker.py", line 73, in run_compliance_tests
    summary_metrics = self.calculate_summary_metrics(fund)
                      ^^^^^^^^^^^^^^^^^^^^^^^^^^^^^^^^^^^^
  File "C:\Users\PatrickCorcoran\OneDrive - Vest Financial\Documents\Coding\VestFundManager\services\compliance_checker.py", line 103, in calculate_summary_metrics
    'equity_market_value': fund.total_equity_value,
                           ^^^^^^^^^^^^^^^^^^^^^^^
  File "C:\Users\PatrickCorcoran\OneDrive - Vest Financial\Documents\Coding\VestFundManager\domain\fund.py", line 72, in total_equity_value
    return (self.data.current.equity['price'] * self.data.current.equity['quantity']).sum()
            ~~~~~~~~~~~~~~~~~~~~~~~~^^^^^^^^^
  File "C:\Users\PatrickCorcoran\anaconda3\Lib\site-packages\pandas\core\frame.py", line 3893, in __getitem__
    indexer = self.columns.get_loc(key)
              ^^^^^^^^^^^^^^^^^^^^^^^^^
  File "C:\Users\PatrickCorcoran\anaconda3\Lib\site-packages\pandas\core\indexes\base.py", line 3798, in get_loc
    raise KeyError(key) from err
KeyError: 'price'
2025-10-25 17:38:32,037 - compliance_checker - ERROR - Error executing gics_compliance for fund DOGG: 'ComplianceChecker' object has no attribute 'fund_results'
Traceback (most recent call last):
  File "C:\Users\PatrickCorcoran\OneDrive - Vest Financial\Documents\Coding\VestFundManager\services\compliance_checker.py", line 85, in run_compliance_tests
    result = test_func(fund)
             ^^^^^^^^^^^^^^^
  File "C:\Users\PatrickCorcoran\OneDrive - Vest Financial\Documents\Coding\VestFundManager\services\compliance_checker.py", line 320, in gics_compliance
    fund_data = self.fund_results.get(etf, {})
                ^^^^^^^^^^^^^^^^^
AttributeError: 'ComplianceChecker' object has no attribute 'fund_results'
2025-10-25 17:38:32,039 - compliance_checker - ERROR - Error executing diversification_40act_check for fund DOGG: 'Fund' object has no attribute 'is_private_fund'
Traceback (most recent call last):
  File "C:\Users\PatrickCorcoran\OneDrive - Vest Financial\Documents\Coding\VestFundManager\services\compliance_checker.py", line 85, in run_compliance_tests
    result = test_func(fund)
             ^^^^^^^^^^^^^^^
  File "C:\Users\PatrickCorcoran\OneDrive - Vest Financial\Documents\Coding\VestFundManager\services\compliance_checker.py", line 221, in diversification_40act_check
    if fund.is_private_fund:
       ^^^^^^^^^^^^^^^^^^^^
AttributeError: 'Fund' object has no attribute 'is_private_fund'
2025-10-25 18:04:26,462 - compliance_checker - INFO - Running compliance tests for DOGG
2025-10-25 18:04:26,462 - compliance_checker - ERROR - Error calculating summary metrics for DOGG: 'Fund' object has no attribute 'data'
Traceback (most recent call last):
  File "C:\Users\PatrickCorcoran\OneDrive - Vest Financial\Documents\Coding\VestFundManager\services\compliance_checker.py", line 73, in run_compliance_tests
    summary_metrics = self.calculate_summary_metrics(fund)
                      ^^^^^^^^^^^^^^^^^^^^^^^^^^^^^^^^^^^^
  File "C:\Users\PatrickCorcoran\OneDrive - Vest Financial\Documents\Coding\VestFundManager\services\compliance_checker.py", line 102, in calculate_summary_metrics
    'cash_value': fund.cash_value,
                  ^^^^^^^^^^^^^^^
  File "C:\Users\PatrickCorcoran\OneDrive - Vest Financial\Documents\Coding\VestFundManager\domain\fund.py", line 87, in cash_value
    return self.data.current.cash
           ^^^^^^^^^
AttributeError: 'Fund' object has no attribute 'data'
2025-10-25 18:04:26,464 - compliance_checker - ERROR - Error executing gics_compliance for fund DOGG: 'ComplianceChecker' object has no attribute 'fund_results'
Traceback (most recent call last):
  File "C:\Users\PatrickCorcoran\OneDrive - Vest Financial\Documents\Coding\VestFundManager\services\compliance_checker.py", line 85, in run_compliance_tests
    result = test_func(fund)
             ^^^^^^^^^^^^^^^
  File "C:\Users\PatrickCorcoran\OneDrive - Vest Financial\Documents\Coding\VestFundManager\services\compliance_checker.py", line 320, in gics_compliance
    fund_data = self.fund_results.get(etf, {})
                ^^^^^^^^^^^^^^^^^
AttributeError: 'ComplianceChecker' object has no attribute 'fund_results'
2025-10-25 18:04:26,466 - compliance_checker - ERROR - Error executing diversification_40act_check for fund DOGG: 'Fund' object has no attribute 'is_private_fund'
Traceback (most recent call last):
  File "C:\Users\PatrickCorcoran\OneDrive - Vest Financial\Documents\Coding\VestFundManager\services\compliance_checker.py", line 85, in run_compliance_tests
    result = test_func(fund)
             ^^^^^^^^^^^^^^^
  File "C:\Users\PatrickCorcoran\OneDrive - Vest Financial\Documents\Coding\VestFundManager\services\compliance_checker.py", line 221, in diversification_40act_check
    if fund.is_private_fund:
       ^^^^^^^^^^^^^^^^^^^^
AttributeError: 'Fund' object has no attribute 'is_private_fund'
2025-10-25 18:05:05,747 - compliance_checker - INFO - Running compliance tests for DOGG
2025-10-25 18:16:34,541 - compliance_checker - INFO - Running compliance tests for DOGG
2025-10-25 18:16:34,542 - compliance_checker - ERROR - Error calculating summary metrics for DOGG: 'Fund' object has no attribute 'data'
Traceback (most recent call last):
  File "C:\Users\PatrickCorcoran\OneDrive - Vest Financial\Documents\Coding\VestFundManager\services\compliance_checker.py", line 73, in run_compliance_tests
    summary_metrics = self.calculate_summary_metrics(fund)
                      ^^^^^^^^^^^^^^^^^^^^^^^^^^^^^^^^^^^^
  File "C:\Users\PatrickCorcoran\OneDrive - Vest Financial\Documents\Coding\VestFundManager\services\compliance_checker.py", line 102, in calculate_summary_metrics
    'cash_value': fund.cash_value,
                  ^^^^^^^^^^^^^^^
  File "C:\Users\PatrickCorcoran\OneDrive - Vest Financial\Documents\Coding\VestFundManager\domain\fund.py", line 87, in cash_value
    return self.data.current.cash
           ^^^^^^^^^
AttributeError: 'Fund' object has no attribute 'data'
2025-10-25 18:16:34,543 - compliance_checker - ERROR - Error executing gics_compliance for fund DOGG: 'ComplianceChecker' object has no attribute 'fund_results'
Traceback (most recent call last):
  File "C:\Users\PatrickCorcoran\OneDrive - Vest Financial\Documents\Coding\VestFundManager\services\compliance_checker.py", line 85, in run_compliance_tests
    result = test_func(fund)
             ^^^^^^^^^^^^^^^
  File "C:\Users\PatrickCorcoran\OneDrive - Vest Financial\Documents\Coding\VestFundManager\services\compliance_checker.py", line 320, in gics_compliance
    fund_data = self.fund_results.get(etf, {})
                ^^^^^^^^^^^^^^^^^
AttributeError: 'ComplianceChecker' object has no attribute 'fund_results'
2025-10-25 18:16:34,545 - compliance_checker - ERROR - Error executing diversification_40act_check for fund DOGG: 'Fund' object has no attribute 'is_private_fund'
Traceback (most recent call last):
  File "C:\Users\PatrickCorcoran\OneDrive - Vest Financial\Documents\Coding\VestFundManager\services\compliance_checker.py", line 85, in run_compliance_tests
    result = test_func(fund)
             ^^^^^^^^^^^^^^^
  File "C:\Users\PatrickCorcoran\OneDrive - Vest Financial\Documents\Coding\VestFundManager\services\compliance_checker.py", line 221, in diversification_40act_check
    if fund.is_private_fund:
       ^^^^^^^^^^^^^^^^^^^^
AttributeError: 'Fund' object has no attribute 'is_private_fund'
2025-10-25 19:02:13,953 - compliance_checker - INFO - Running compliance tests for DOGG
2025-10-25 19:02:13,953 - compliance_checker - ERROR - Error calculating summary metrics for DOGG: 'Fund' object has no attribute 'data'
Traceback (most recent call last):
  File "C:\Users\PatrickCorcoran\OneDrive - Vest Financial\Documents\Coding\VestFundManager\services\compliance_checker.py", line 73, in run_compliance_tests
    summary_metrics = self.calculate_summary_metrics(fund)
                      ^^^^^^^^^^^^^^^^^^^^^^^^^^^^^^^^^^^^
  File "C:\Users\PatrickCorcoran\OneDrive - Vest Financial\Documents\Coding\VestFundManager\services\compliance_checker.py", line 102, in calculate_summary_metrics
    'cash_value': fund.cash_value,
                  ^^^^^^^^^^^^^^^
  File "C:\Users\PatrickCorcoran\OneDrive - Vest Financial\Documents\Coding\VestFundManager\domain\fund.py", line 87, in cash_value
    return self.data.current.cash
           ^^^^^^^^^
AttributeError: 'Fund' object has no attribute 'data'
2025-10-25 19:02:13,956 - compliance_checker - ERROR - Error executing gics_compliance for fund DOGG: 'ComplianceChecker' object has no attribute 'fund_results'
Traceback (most recent call last):
  File "C:\Users\PatrickCorcoran\OneDrive - Vest Financial\Documents\Coding\VestFundManager\services\compliance_checker.py", line 85, in run_compliance_tests
    result = test_func(fund)
             ^^^^^^^^^^^^^^^
  File "C:\Users\PatrickCorcoran\OneDrive - Vest Financial\Documents\Coding\VestFundManager\services\compliance_checker.py", line 320, in gics_compliance
    fund_data = self.fund_results.get(etf, {})
                ^^^^^^^^^^^^^^^^^
AttributeError: 'ComplianceChecker' object has no attribute 'fund_results'
2025-10-25 19:02:13,957 - compliance_checker - ERROR - Error executing diversification_40act_check for fund DOGG: 'Fund' object has no attribute 'is_private_fund'
Traceback (most recent call last):
  File "C:\Users\PatrickCorcoran\OneDrive - Vest Financial\Documents\Coding\VestFundManager\services\compliance_checker.py", line 85, in run_compliance_tests
    result = test_func(fund)
             ^^^^^^^^^^^^^^^
  File "C:\Users\PatrickCorcoran\OneDrive - Vest Financial\Documents\Coding\VestFundManager\services\compliance_checker.py", line 221, in diversification_40act_check
    if fund.is_private_fund:
       ^^^^^^^^^^^^^^^^^^^^
AttributeError: 'Fund' object has no attribute 'is_private_fund'
2025-10-25 19:33:45,657 - compliance_checker - INFO - Running compliance tests for DOGG
2025-10-25 19:33:45,659 - compliance_checker - ERROR - Error executing gics_compliance for fund DOGG: 'ComplianceChecker' object has no attribute 'fund_results'
Traceback (most recent call last):
  File "C:\Users\PatrickCorcoran\OneDrive - Vest Financial\Documents\Coding\VestFundManager\services\compliance_checker.py", line 85, in run_compliance_tests
    result = test_func(fund)
             ^^^^^^^^^^^^^^^
  File "C:\Users\PatrickCorcoran\OneDrive - Vest Financial\Documents\Coding\VestFundManager\services\compliance_checker.py", line 320, in gics_compliance
    fund_data = self.fund_results.get(etf, {})
                ^^^^^^^^^^^^^^^^^
AttributeError: 'ComplianceChecker' object has no attribute 'fund_results'
2025-10-25 19:39:00,161 - compliance_checker - INFO - Running compliance tests for DOGG
2025-10-25 19:39:00,164 - compliance_checker - ERROR - Error executing gics_compliance for fund DOGG: 'ComplianceChecker' object has no attribute 'fund_results'
Traceback (most recent call last):
  File "C:\Users\PatrickCorcoran\OneDrive - Vest Financial\Documents\Coding\VestFundManager\services\compliance_checker.py", line 85, in run_compliance_tests
    result = test_func(fund)
             ^^^^^^^^^^^^^^^
  File "C:\Users\PatrickCorcoran\OneDrive - Vest Financial\Documents\Coding\VestFundManager\services\compliance_checker.py", line 320, in gics_compliance
    fund_data = self.fund_results.get(etf, {})
                ^^^^^^^^^^^^^^^^^
AttributeError: 'ComplianceChecker' object has no attribute 'fund_results'
2025-10-25 20:09:49,607 - compliance_checker - INFO - Running compliance tests for DOGG
2025-10-25 21:20:39,165 - compliance_checker - INFO - Running compliance tests for DOGG
2025-10-25 21:23:51,292 - compliance_checker - INFO - Running compliance tests for DOGG
2025-10-25 21:51:20,572 - compliance_checker - INFO - Running compliance tests for DOGG
2025-10-26 09:57:49,026 - compliance_checker - INFO - Running compliance tests for DOGG
2025-10-26 10:10:30,711 - compliance_checker - INFO - Running compliance tests for DOGG
2025-10-26 19:19:18,547 - compliance_checker - INFO - Running compliance tests for DOGG
2025-10-26 19:19:18,573 - compliance_checker - ERROR - Error in IRS diversification check for DOGG: Cannot set non-string value '0.0' into a StringArray.
2025-10-26 19:19:18,609 - compliance_checker - ERROR - Error in IRC diversification check for DOGG: Cannot set non-string value '0.0' into a StringArray.
2025-10-26 19:51:32,276 - compliance_checker - INFO - Running compliance tests for DOGG
2025-10-26 19:51:32,496 - compliance_checker - ERROR - Error in IRS diversification check for DOGG: Cannot set non-string value '0.0' into a StringArray.
2025-10-26 19:51:32,761 - compliance_checker - ERROR - Error in IRC diversification check for DOGG: Cannot set non-string value '0.0' into a StringArray.
2025-10-26 19:57:11,916 - compliance_checker - INFO - Running compliance tests for DOGG
2025-10-26 19:57:11,938 - compliance_checker - ERROR - Error in IRS diversification check for DOGG: Cannot set non-string value '0.0' into a StringArray.
2025-10-26 19:57:11,973 - compliance_checker - ERROR - Error in IRC diversification check for DOGG: Cannot set non-string value '0.0' into a StringArray.
2025-10-26 20:03:55,841 - compliance_checker - INFO - Running compliance tests for DOGG
2025-10-26 20:03:55,865 - compliance_checker - ERROR - Error in IRS diversification check for DOGG: Cannot set non-string value '0.0' into a StringArray.
2025-10-26 20:03:55,901 - compliance_checker - ERROR - Error in IRC diversification check for DOGG: Cannot set non-string value '0.0' into a StringArray.
2025-10-26 20:07:14,660 - compliance_checker - INFO - Running compliance tests for DOGG
2025-10-26 20:07:14,684 - compliance_checker - ERROR - Error in IRS diversification check for DOGG: Cannot set non-string value '0.0' into a StringArray.
2025-10-26 20:07:14,718 - compliance_checker - ERROR - Error in IRC diversification check for DOGG: Cannot set non-string value '0.0' into a StringArray.
2025-10-26 20:08:31,909 - compliance_checker - INFO - Running compliance tests for DOGG
2025-10-26 20:08:32,153 - compliance_checker - ERROR - Error in IRS diversification check for DOGG: Cannot set non-string value '0.0' into a StringArray.
2025-10-26 20:08:32,426 - compliance_checker - ERROR - Error in IRC diversification check for DOGG: Cannot set non-string value '0.0' into a StringArray.
2025-10-26 20:16:52,293 - compliance_checker - INFO - Running compliance tests for DOGG
2025-10-26 20:16:52,508 - compliance_checker - ERROR - Error in IRS diversification check for DOGG: Cannot set non-string value '0.0' into a StringArray.
2025-10-26 20:16:52,768 - compliance_checker - ERROR - Error in IRC diversification check for DOGG: Cannot set non-string value '0.0' into a StringArray.
2025-10-26 20:26:43,875 - compliance_checker - INFO - Running compliance tests for DOGG
2025-10-26 21:07:14,765 - compliance_checker - INFO - Running compliance tests for DOGG
2025-10-26 21:15:40,717 - compliance_checker - INFO - Running compliance tests for DOGG
2025-10-26 21:16:41,349 - compliance_checker - INFO - Running compliance tests for DOGG
2025-10-26 22:47:50,445 - compliance_checker - INFO - Running compliance tests for DOGG
2025-10-27 12:36:27,185 - compliance_checker - INFO - Running compliance tests for DOGG
2025-10-28 11:58:58,745 - compliance_checker - INFO - Running compliance tests for DOGG
2025-10-28 12:18:06,660 - compliance_checker - INFO - Running compliance tests for DOGG
2025-10-28 20:59:29,720 - compliance_checker - INFO - Running compliance tests for DOGG
2025-10-28 22:31:34,667 - compliance_checker - INFO - Running compliance tests for DOGG
2025-10-28 22:34:02,172 - compliance_checker - INFO - Running compliance tests for DOGG
2025-10-28 22:37:06,015 - compliance_checker - INFO - Running compliance tests for DOGG
2025-10-28 23:08:30,615 - compliance_checker - INFO - Running compliance tests for DOGG
2025-10-28 23:08:30,694 - compliance_checker - ERROR - Error in IRC diversification check for DOGG: Equity holdings missing
2025-10-28 23:08:30,704 - compliance_checker - ERROR - Error in SAI illiquidity check for DOGG: Equity holdings or total assets missing
2025-10-28 23:08:30,715 - compliance_checker - ERROR - Error in real estate check for DOGG: Equity holdings missing
2025-10-28 23:08:30,728 - compliance_checker - ERROR - Error in commodities check for DOGG: Equity holdings missing
2025-10-28 23:08:30,744 - compliance_checker - ERROR - Error in 12d1-1 check for DOGG: Equity holdings or total assets missing
2025-10-28 23:10:04,895 - compliance_checker - INFO - Running compliance tests for DOGG
2025-10-28 23:10:04,965 - compliance_checker - ERROR - Error in IRC diversification check for DOGG: Equity holdings missing
2025-10-28 23:10:04,976 - compliance_checker - ERROR - Error in SAI illiquidity check for DOGG: Equity holdings or total assets missing
2025-10-28 23:10:04,985 - compliance_checker - ERROR - Error in real estate check for DOGG: Equity holdings missing
2025-10-28 23:10:04,995 - compliance_checker - ERROR - Error in commodities check for DOGG: Equity holdings missing
2025-10-28 23:10:05,006 - compliance_checker - ERROR - Error in 12d1-1 check for DOGG: Equity holdings or total assets missing
2025-10-28 23:11:28,330 - compliance_checker - INFO - Running compliance tests for DOGG
2025-10-28 23:11:28,407 - compliance_checker - ERROR - Error in IRC diversification check for DOGG: Equity holdings missing
2025-10-28 23:11:28,416 - compliance_checker - ERROR - Error in SAI illiquidity check for DOGG: Equity holdings or total assets missing
2025-10-28 23:11:28,426 - compliance_checker - ERROR - Error in real estate check for DOGG: Equity holdings missing
2025-10-28 23:11:28,435 - compliance_checker - ERROR - Error in commodities check for DOGG: Equity holdings missing
2025-10-28 23:11:28,445 - compliance_checker - ERROR - Error in 12d1-1 check for DOGG: Equity holdings or total assets missing
2025-10-28 23:12:52,859 - compliance_checker - INFO - Running compliance tests for DOGG
2025-10-28 23:31:13,756 - compliance_checker - INFO - Running compliance tests for DOGG
2025-10-28 23:47:00,599 - compliance_checker - INFO - Running compliance tests for DOGG
2025-10-28 23:50:14,810 - compliance_checker - INFO - Running compliance tests for DOGG
2025-10-29 00:04:06,156 - compliance_checker - INFO - Running compliance tests for DOGG
2025-10-29 00:14:22,452 - compliance_checker - INFO - Running compliance tests for DOGG
2025-10-29 07:13:36,122 - compliance_checker - INFO - Running compliance tests for DOGG
2025-10-29 07:22:03,367 - compliance_checker - INFO - Running compliance tests for DOGG
2025-10-29 07:24:38,523 - compliance_checker - INFO - Running compliance tests for DOGG
2025-10-29 08:02:59,441 - compliance_checker - INFO - Running compliance tests for DOGG
2025-10-29 08:02:59,453 - compliance_checker - ERROR - Error in prospectus policy check for DOGG: 'Fund' object has no attribute '_extract_nav_metric'
2025-10-29 08:02:59,462 - compliance_checker - ERROR - Error in IRS diversification check for DOGG: 'Fund' object has no attribute '_extract_nav_metric'
2025-10-29 08:02:59,474 - compliance_checker - ERROR - Error in 40 Act diversification check for DOGG: 'Fund' object has no attribute '_extract_nav_metric'
2025-10-29 08:02:59,486 - compliance_checker - ERROR - Error in IRC diversification check for DOGG: 'Fund' object has no attribute '_extract_nav_metric'
2025-10-29 08:02:59,497 - compliance_checker - ERROR - Error in SAI illiquidity check for DOGG: 'Fund' object has no attribute '_extract_nav_metric'
2025-10-29 08:02:59,527 - compliance_checker - ERROR - Error in 12d1-1 check for DOGG: 'Fund' object has no attribute '_extract_nav_metric'
2025-10-29 08:02:59,536 - compliance_checker - ERROR - Error in 12d-2 check for DOGG: 'Fund' object has no attribute '_extract_nav_metric'
2025-10-29 08:02:59,546 - compliance_checker - ERROR - Error in 12d-3 check for DOGG: 'Fund' object has no attribute '_extract_nav_metric'
2025-10-29 08:04:07,577 - compliance_checker - INFO - Running compliance tests for DOGG
2025-10-29 08:07:17,767 - compliance_checker - INFO - Running compliance tests for DOGG
2025-10-29 08:28:43,515 - compliance_checker - INFO - Running compliance tests for DOGG
2025-10-29 11:49:43,919 - compliance_checker - INFO - Running compliance tests for DOGG
2025-10-29 11:49:44,125 - compliance_checker - INFO - Running compliance tests for DOGG
2025-10-29 11:49:44,220 - compliance_checker - ERROR - Error in SAI illiquidity check for DOGG: Equity holdings or total assets missing
2025-10-29 11:49:44,234 - compliance_checker - ERROR - Error in real estate check for DOGG: Equity holdings missing
2025-10-29 11:49:44,245 - compliance_checker - ERROR - Error in commodities check for DOGG: Equity holdings missing
2025-10-29 11:49:44,258 - compliance_checker - ERROR - Error in 12d1-1 check for DOGG: Equity holdings or total assets missing
2025-10-29 12:49:32,283 - compliance_checker - INFO - Running compliance tests for DOGG
2025-10-29 20:12:55,528 - compliance_checker - INFO - Running compliance tests for DOGG
2025-10-29 20:19:27,557 - compliance_checker - INFO - Running compliance tests for DOGG
2025-10-29 20:19:27,712 - compliance_checker - ERROR - Error in SAI illiquidity check for DOGG: Equity holdings or total assets missing
2025-10-29 20:19:27,751 - compliance_checker - ERROR - Error in 12d1-1 check for DOGG: Equity holdings or total assets missing
